Workbook

Sheet KLUS
A1: KOD Kluś | B1: EAN Kluś | C1: Nazwa Kluś | D1: Opis Kluś | E1: Cena hurt Kluś
A2: B8288ANODA_1 | B2: 5902280310303 | C2: Profil PIKO anoda e6-k1 1m | D2: Stosować z osłonką nr ref. 17034, zaślepka 24202, 24299 | E2: 13.2
A3: B8288ANODA_2 | B3: 5902280307082 | C3: Profil PIKO anoda e6-k1 2m | D3: Stosować z osłonką nr ref. 17034, zaślepka 24202, 24299 | E3: 26.5
A4: B8288ANODA_3 | B4: 5902280310228 | C4: Profil PIKO anoda e6-k1 3m | D4: Stosować z osłonką nr ref. 17034, zaślepka 24202, 24299 | E4: 39.7
A5: B8288K7_1 | B5: 5902280338079 | C5: Profil PIKO anoda e6-k7 1m | D5: Stosować z osłonką nr ref. 17034, zaślepka 24379, 24399 | E5: 14.4
A6: B8288K7_2 | B6: 5902280338055 | C6: Profil PIKO anoda e6-k7 2m | D6: Stosować z osłonką nr ref. 17034, zaślepka 24379, 24399 | E6: 28.8
A7: B8288K7_3 | B7: 5902280338062 | C7: Profil PIKO anoda e6-k7 3m | D7: Stosować z osłonką nr ref. 17034, zaślepka 24379, 24399 | E7: 43.1
A8: C1167ANODA_1 | B8: 5902280322252 | C8: Profil PIKO-O anoda e6-k1 1m | D8: Stosować z osłonką nr ref. 17164, zaślepka 24321 | E8: 13.1
A9: C1167ANODA_2 | B9: 5902280319887 | C9: Profil PIKO-O anoda e6-k1 2m | D9: Stosować z osłonką nr ref. 17164, zaślepka 24321 | E9: 26.2
A10: C1167ANODA_3 | B10: 5902280322009 | C10: Profil PIKO-O anoda e6-k1 3m | D10: Stosować z osłonką nr ref. 17164, zaślepka 24321 | E10: 39.3
A11: C1167K7_1 | B11: 5902280327677 | C11: Profil PIKO-O anoda e6-k7 1m | D11: Stosować z osłonką nr ref. 17164, zaślepka 24327 | E11: 14
A12: C1167K7_2 | B12: 5902280326182 | C12: Profil PIKO-O anoda e6-k7 2m | D12: Stosować z osłonką nr ref. 17164, zaślepka 24327 | E12: 28
A13: C1167K7_3 | B13: 5902280326175 | C13: Profil PIKO-O anoda e6-k7 3m | D13: Stosować z osłonką nr ref. 17164, zaślepka 24327 | E13: 42
... A109: B9325L9010OD_2 | B109: 5902280348412 | C109: Profil SILER lakier ral9010 2m | D109: Profil anodowany, stosować z zaślepka ref. 24382, 42630, 24407, pasujące osłony 17039, 17049 | E109: 61.4
A110: B1718NA_2 | B110: 5906660780038 | C110: Profil led PDS4 2m | E110: 23.9
A113: C1587ANODA_1 | B113: 5902280330059 | C113: Profil MICRO-NK anoda e6-k1 1m | D113: Profil anodowany, Używać z zaślepkami 24346, 24347 i osłonkami ref. 17071, 17072, 17037 | E113: 19.3
A114: C1587ANODA_2 | B114: 5902280327059 | C114: Profil MICRO-NK anoda e6-k1 2m | D114: Profil anodowany, Używać z zaślepkami 24346, 24347 i osłonkami ref. 17071, 17072, 17037 | E114: 37.6
A115: C1587ANODA_3 | B115: 5902280328094 | C115: Profil MICRO-NK anoda e6-k1 3m | D115: Profil anodowany, Używać z zaślepkami 24346, 24347 i osłonkami ref. 17071, 17072, 17037 | E115: 57.8
A116: C1587K7_1 | B116: 5902280334484 | C116: Profil MICRO-NK anoda e6-k7 1m | D116: Profil anodowany, Używać z zaślepkami 24362, 24363 i osłonkami ref. 17071, 17072, 17037 | E116: 21.4
A117: C1587K7_2 | B117: 5902280332602 | C117: Profil MICRO-NK anoda e6-k7 2m | D117: Profil anodowany, Używać z zaślepkami 24362, 24363 i osłonkami ref. 17071, 17072, 17037 | E117: 42.7
A118: C1587K7_3 | B118: 5902280333807 | C118: Profil MICRO-NK anoda e6-k7 3m | D118: Profil anodowany, Używać z zaślepkami 24362, 24363 i osłonkami ref. 17071, 17072, 17037 | E118: 64.1
A119: C1587L9010OD_1 | B119: 5902280348733 | C119: Profil MICRO-NK lakier ral9010 1m | D119: Profil anodowany, Używać z zaślepkami 24362, 24363, 24408, 24409 i osłonkami ref. 17071, 17072, 17037 | E119: 22.6
A120: C1587L9010OD_2 | B120: 5902280348726 | C120: Profil MICRO-NK lakier ral9010 2m | D120: Profil anodowany, Używać z zaślepkami 24362, 24363, 24408, 24409 i osłonkami ref. 17071, 17072, 17037 | E120: 45.2
A121: C1588ANODA_1 | B121: 5902280330035 | C121: Profil PDS-NK anoda e6-k1 1m | D121: Profil anodowany, Używać z zaślepkami ref.24338, 24339 i osłonkami ref. 17071, 17072, 17037 | E121: 19.3
A122: C1588ANODA_2 | B122: 5902280327066 | C122: Profil PDS-NK anoda e6-k1 2m | D122: Profil anodowany, Używać z zaślepkami ref.24338, 24339 i osłonkami ref. 17071, 17072, 17037 | E122: 38.5
A123: C1588ANODA_3 | B123: 5902280328087 | C123: Profil PDS-NK anoda e6-k1 3m | D123: Profil anodowany, Używać z zaślepkami ref.24338, 24339 i osłonkami ref. 17071, 17072, 17037 | E123: 57.8
A124: C1588K7_1 | B124: 5902280330042 | C124: Profil PDS-NK anoda e6-k7 1m | D124: Profil anodowany, Używać z zaślepkami ref. 24342, 24343 i osłonkami ref. 17071, 17072, 17037 | E124: 22.8
... A534: B8338NA_2 | B534: 5902280308119 | C534: Profil FOLHAK surowy 2m | D534: Profil anodowany, stosować z ref. 79106, B8332NA, B8333NA, B8334NA | E534: 15.3
A535: H1179L9010OD_1 | B535: 5902280354598 | C535: Profil POKET lakier RAL9010 1m | E535: 227
A536: H1179L9010OD_2 | B536: 5902280352815 | C536: Profil POKET lakier RAL9010 2m | E536: 453.9
A537: H1179L9010OD_3 | B537: 5902280352822 | C537: Profil POKET lakier RAL9010 3m | E537: 680.9
A538: H1179NA_1 | B538: 5902280354604 | C538: Profil POKET surowy 1000 | E538: 109.7
A539: H1179NA_2 | B539: 5902280345756 | C539: Profil POKET surowy 2005 | E539: 219.4
A540: H1179NA_3 | B540: 5902280345787 | C540: Profil POKET surowy 3m | E540: 306.2
A541: H1234L9010OD_1 | B541: 5902280354611 | C541: Profil POK-US lakier RAL9010 1m | E541: 163.8
A542: H1234L9010OD_2 | B542: 5902280352877 | C542: Profil POK-US lakier RAL9010 2m | E542: 327.5
A543: H1234L9010OD_3 | B543: 5902280352884 | C543: Profil POK-US lakier RAL9010 3m | E543: 473.9
A544: H1234NA_1 | B544: 5902280354628 | C544: Profil POK-US surowy 1m | E544: 106.2
A545: H1234NA_2 | B545: 5902280345763 | C545: Profil POK-US surowy 2m | E545: 212.4
A546: H1234NA_3 | B546: 5902280345800 | C546: Profil POK-US surowy 3m | E546: 310.3
...

Sheet Baza WFMAG
A1: Artykuł | B1: Nr katalogowy | C1: VAT zakupu | D1: Waluta zakupu | E1: Cena zakupu netto | F1: Cena zakupu brutto | G1: IdCeny | H1: Cena | I1: Netto | J1: Brutto | K1: Tryb | L1: VAT sprzedaży | M1: Waluta sprzedaży
A2: Baza okragła do lampy Patyk-26 Fornir Kluś | B2: KLU-AKC-00014 | G2: 1 | H2: Detaliczna | I2: 353.4 | J2: 434.68 | K2: netto | L2: 23
A3: Baza okragła do lampy Patyk-26 Fornir Kluś | B3: KLU-AKC-00014 | G3: 2 | H3: Hurtowa | I3: 353.4 | J3: 434.68 | K3: netto | L3: 23
A4: Blokada ZD do zamka Kluś | B4: 1775 | G4: 1 | H4: Detaliczna | I4: 8.29 | J4: 10.2 | K4: netto | L4: 23
A5: Blokada ZD do zamka Kluś | B5: 1775 | G5: 2 | H5: Hurtowa | I5: 8.3 | J5: 10.21 | K5: netto | L5: 23
A6: Broszura profile i akcesoria PL-EN v6 Kluś | B6: Pro000093 | G6: 1 | H6: Detaliczna | I6: 2.03 | J6: 2.5 | K6: netto | L6: 23
A7: Broszura profile i akcesoria PL-EN v6 Kluś | B7: Pro000093 | G7: 2 | H7: Hurtowa | I7: 1 | J7: 1.23 | K7: netto | L7: 23
A8: Dławnica 16x1.5 Kluś | B8: KLU-AKC-00019 | G8: 1 | H8: Detaliczna | I8: 6.5 | J8: 8 | K8: netto | L8: 23
A9: Dławnica 16x1.5 Kluś | B9: KLU-AKC-00019 | G9: 2 | H9: Hurtowa | I9: 6 | J9: 7.38 | K9: netto | L9: 23
A10: Dławnica 16x1.5 M16 Skintop ST-M Kluś | B10: 1799 | G10: 1 | H10: Detaliczna | I10: 4.73 | J10: 5.82 | K10: netto | L10: 23
A11: Dławnica 16x1.5 M16 Skintop ST-M Kluś | B11: 1799 | G11: 2 | H11: Hurtowa | I11: 4.73 | J11: 5.82 | K11: netto | L11: 23
A12: Dławnica 24x1 6 Kluś | B12: 820 | G12: 1 | H12: Detaliczna | I12: 1.14 | J12: 1.4 | K12: netto | L12: 23
A13: Dławnica 24x1 6 Kluś | B13: 820 | G13: 2 | H13: Hurtowa | I13: 0.9 | J13: 1.11 | K13: netto | L13: 23
A14: Dławnica 6x1.2 Kluś | B14: KAT00105 | G14: 1 | H14: Detaliczna | I14: 1.22 | J14: 1.5 | K14: netto | L14: 23
A15: Dławnica 6x1.2 Kluś | B15: KAT00105 | G15: 2 | H15: Hurtowa | I15: 1 | J15: 1.23 | K15: netto | L15: 23
A16: Dławnica 8.8x2.0 Kluś | B16: 00802L | G16: 1 | H16: Detaliczna | I16: 0.89 | J16: 1.09 | K16: netto | L16: 23
A17: Dławnica 8.8x2.0 Kluś | B17: 00802L | G17: 2 | H17: Hurtowa | I17: 0.7 | J17: 0.86 | K17: netto | L17: 23
A18: Dławnica 8x1 Kluś | B18: 1351 | G18: 1 | H18: Detaliczna | I18: 26.95 | J18: 33.15 | K18: netto | L18: 23
A19: Dławnica 8x1 Kluś | B19: 1351 | G19: 2 | H19: Hurtowa | I19: 26.95 | J19: 33.15 | K19: netto | L19: 23
A20: Dławnica 8x1,6 Kluś | B20: Pro000028 | G20: 1 | H20: Detaliczna | I20: 1.06 | J20: 1.3 | K20: netto | L20: 23
A21: Dławnica 8x1,6 Kluś | B21: Pro000028 | G21: 2 | H21: Hurtowa | I21: 1.06 | J21: 1.3 | K21: netto | L21: 23
A22: Dławnica 9.5x4x6.4x3x8 Gland Kluś | B22: KLU-AKC-00020 | G22: 1 | H22: Detaliczna | I22: 0.98 | J22: 1.21 | K22: netto | L22: 23
A23: Dławnica 9.5x4x6.4x3x8 Gland Kluś | B23: KLU-AKC-00020 | G23: 2 | H23: Hurtowa | I23: 0.8 | J23: 0.98 | K23: netto | L23: 23
A24: Dławnica kątowa 16x1.5-l90 Kluś | B24: 1718 | G24: 1 | H24: Detaliczna | I24: 36.34 | J24: 44.7 | K24: netto | L24: 23
A25: Dławnica kątowa 16x1.5-l90 Kluś | B25: 1718 | G25: 2 | H25: Hurtowa | I25: 36.3 | J25: 44.65 | K25: netto | L25: 23
A26: Głowica 45-ST Kluś | B26: 42210 | G26: 1 | H26: Detaliczna | I26: 14.15 | J26: 17.4 | K26: netto | L26: 23
A27: Głowica 45-ST Kluś | B27: 42210 | G27: 2 | H27: Hurtowa | I27: 11.3 | J27: 13.9 | K27: netto | L27: 23
A28: Głowica 45-ZO Kluś | B28: 42211 | G28: 1 | H28: Detaliczna | I28: 19.8 | J28: 24.35 | K28: netto | L28: 23
A29: Głowica 45-ZO Kluś | B29: 42211 | G29: 2 | H29: Hurtowa | I29: 19.8 | J29: 24.35 | K29: netto | L29: 23
A30: Kabel YvKSLY 2x0.5mm2 Kluś | B30: KLU-AKC-00027 | G30: 1 | H30: Detaliczna | I30: 6.67 | J30: 8.2 | K30: netto | L30: 23
A31: Kabel YvKSLY 2x0.5mm2 Kluś | B31: KLU-AKC-00027 | G31: 2 | H31: Hurtowa | I31: 5.3 | J31: 6.52 | K31: netto | L31: 23
A32: Kabel YvKSLY 2x0.75mm2 Kluś | B32: 1719 | G32: 1 | H32: Detaliczna | I32: 7.64 | J32: 9.4 | K32: netto | L32: 23
A33: Kabel YvKSLY 2x0.75mm2 Kluś | B33: 1719 | G33: 2 | H33: Hurtowa | I33: 7.6 | J33: 9.35 | K33: netto | L33: 23
A34: Katalog Kluś POL-ANG v9 | B34: Pro000098 | G34: 1 | H34: Detaliczna | I34: 6.5 | J34: 8 | K34: netto | L34: 23
A35: Katalog Kluś POL-ANG v9 | B35: Pro000098 | G35: 2 | H35: Hurtowa | I35: 5 | J35: 6.15 | K35: netto | L35: 23
A36: Klips HR-MAX Kluś | B36: 1716 | G36: 1 | H36: Detaliczna | I36: 4.07 | J36: 5.01 | K36: netto | L36: 23
A37: Klips HR-MAX Kluś | B37: 1716 | G37: 2 | H37: Hurtowa | I37: 4.1 | J37: 5.04 | K37: netto | L37: 23
A38: Kołek C11 Kluś | B38: 42117 | G38: 1 | H38: Detaliczna | I38: 9.35 | J38: 11.5 | K38: netto | L38: 23
A39: Kołek C11 Kluś | B39: 42117 | G39: 2 | H39: Hurtowa | I39: 9.08 | J39: 11.17 | K39: netto | L39: 23
A40: Kostka dwutorowa Kluś | B40: 887 | G40: 1 | H40: Detaliczna | I40: 0.92 | J40: 1.13 | K40: netto | L40: 23
...

Sheet PRESCOT kpl
A1: Nazwa cała | B1: R | C1: Cena sprzedaży netto | D1: Nr katalogowy | E1: Indeks handlowy | F1: Kod kreskowy | G1: Indeks producenta | H1: Indeks producenta | I1: Cena hurt Klus | J1: Detal netto | K1: Hurt netto
C2: PRESCOT WFMAG | D2: PRESCOT | E2: PRESCOT | F2: PRESCOT | G2: Profil | H2: Osłona | J2: 0.1 | K2: 0.2
A3: Profil led 45-16 1m anodowany z osłoną mleczną KA | B3: Towar | C3: 27,30 | E3: 45-16-ML-1M-A | F3: 5903684850167 | G3: B8504ANODA_1 | H3: 17035_1 | I3: {=XLOOKUP(G3,KLUS!$A$2:$A$2010,KLUS!$E$2:$E$2010)+XLOOKUP(H3,KLUS!$A$2:$A$2010,KLUS!$E$2:$E$2010)} -> 27.3 | J3: =I3*(1-$J$2) -> 24.57 | K3: =J3*(1-$K$2) -> 19.656
A4: Profil led 45-16 1m anodowany z osłoną mleczną KA-COM | B4: Towar | C4: 21,50 | E4: 45-16-MLC-1M-A | F4: 5901885267586 | G4: B8504ANODA_1 | H4: 17179_1 | I4: {=XLOOKUP(G4,KLUS!$A$2:$A$2010,KLUS!$E$2:$E$2010)+XLOOKUP(H4,KLUS!$A$2:$A$2010,KLUS!$E$2:$E$2010)} -> 21.5 | J4: =I4*(1-$J$2) -> 19.35 | K4: =J4*(1-$K$2) -> 15.48
A5: Profil led 45-16 1m anodowany z osłoną mleczną LIGER | B5: Towar | C5: 30,95 | E5: 45-16-ML-1M-A-L | F5: 5905475360442 | G5: B8504ANODA_1 | H5: 17037_1 | I5: {=XLOOKUP(G5,KLUS!$A$2:$A$2010,KLUS!$E$2:$E$2010)+XLOOKUP(H5,KLUS!$A$2:$A$2010,KLUS!$E$2:$E$2010)} -> 33.7 | J5: =I5*(1-$J$2) -> 30.33 | K5: =J5*(1-$K$2) -> 24.264
A6: Profil led 45-16 1m anodowany z osłoną przeźroczystą KA | B6: Towar | C6: 24,50 | E6: 45-16-CL-1M-A | F6: 5903684850174 | G6: B8504ANODA_1 | H6: 17036_1 | I6: {=XLOOKUP(G6,KLUS!$A$2:$A$2010,KLUS!$E$2:$E$2010)+XLOOKUP(H6,KLUS!$A$2:$A$2010,KLUS!$E$2:$E$2010)} -> 27.3 | J6: =I6*(1-$J$2) -> 24.57 | K6: =J6*(1-$K$2) -> 19.656
A7: Profil led 45-16 1m anodowany z osłoną przeźroczystą KA-COM | B7: Towar | C7: 18,80 | E7: 45-16-CLC-1M-A | F7: 5903684850181 | G7: B8504ANODA_1 | H7: 17122_1 | I7: {=XLOOKUP(G7,KLUS!$A$2:$A$2010,KLUS!$E$2:$E$2010)+XLOOKUP(H7,KLUS!$A$2:$A$2010,KLUS!$E$2:$E$2010)} -> 21.5 | J7: =I7*(1-$J$2) -> 19.35 | K7: =J7*(1-$K$2) -> 15.48
A8: Profil led 45-16 2m anodowany z osłoną mleczną KA | B8: Towar | C8: 35,00 | E8: 45-16-ML-2M-A | F8: 5903684850198 | G8: B8504ANODA_2 | H8: 17035_2 | I8: {=XLOOKUP(G8,KLUS!$A$2:$A$2010,KLUS!$E$2:$E$2010)+XLOOKUP(H8,KLUS!$A$2:$A$2010,KLUS!$E$2:$E$2010)} -> 54.5 | J8: =I8*(1-$J$2) -> 49.05 | K8: =J8*(1-$K$2) -> 39.24
A9: Profil led 45-16 2m anodowany z osłoną mleczną KA-COM | B9: Produkt | C9: 30,00 | E9: 45-16-MLC-2M-A | F9: 5901885267357 | G9: B8504ANODA_2 | H9: 17179_2 | I9: {=XLOOKUP(G9,KLUS!$A$2:$A$2010,KLUS!$E$2:$E$2010)+XLOOKUP(H9,KLUS!$A$2:$A$2010,KLUS!$E$2:$E$2010)} -> 43 | J9: =I9*(1-$J$2) -> 38.7 | K9: =J9*(1-$K$2) -> 30.96
A10: Profil led 45-16 2m anodowany z osłoną mleczną LIGER | B10: Towar | C10: 61,90 | E10: 45-16-ML-2M-A-L | F10: 5905475360459 | G10: B8504ANODA_2 | H10: 17037_2 | I10: {=XLOOKUP(G10,KLUS!$A$2:$A$2010,KLUS!$E$2:$E$2010)+XLOOKUP(H10,KLUS!$A$2:$A$2010,KLUS!$E$2:$E$2010)} -> 67.4 | J10: =I10*(1-$J$2) -> 60.66 | K10: =J10*(1-$K$2) -> 48.528
A11: Profil led 45-16 2m anodowany z osłoną przeźroczystą KA | B11: Towar | C11: 49,00 | E11: 45-16-CL-2M-A | F11: 5903684850204 | G11: B8504ANODA_2 | H11: 17036_2 | I11: {=XLOOKUP(G11,KLUS!$A$2:$A$2010,KLUS!$E$2:$E$2010)+XLOOKUP(H11,KLUS!$A$2:$A$2010,KLUS!$E$2:$E$2010)} -> 54.5 | J11: =I11*(1-$J$2) -> 49.05 | K11: =J11*(1-$K$2) -> 39.24
A12: Profil led 45-16 2m anodowany z osłoną przeźroczystą KA-COM | B12: Towar | C12: 37,60 | E12: 45-16-CLC-2M-A | F12: 5901885267364 | G12: B8504ANODA_2 | H12: 17122_2 | I12: {=XLOOKUP(G12,KLUS!$A$2:$A$2010,KLUS!$E$2:$E$2010)+XLOOKUP(H12,KLUS!$A$2:$A$2010,KLUS!$E$2:$E$2010)} -> 43 | J12: =I12*(1-$J$2) -> 38.7 | K12: =J12*(1-$K$2) -> 30.96
A13: Profil led 45-16 3m anodowany z osłoną mleczną KA | B13: Towar | C13: 73,50 | E13: 45-16-ML-3M-A | F13: 5903684850211 | G13: B8504ANODA_3 | H13: 17035_3 | I13: {=XLOOKUP(G13,KLUS!$A$2:$A$2010,KLUS!$E$2:$E$2010)+XLOOKUP(H13,KLUS!$A$2:$A$2010,KLUS!$E$2:$E$2010)} -> 81.7 | J13: =I13*(1-$J$2) -> 73.53 | K13: =J13*(1-$K$2) -> 58.824
A14: Profil led 45-16 3m anodowany z osłoną mleczną KA-COM | B14: Towar | C14: 56,40 | E14: 45-16-MLC-3M-A | F14: 5901885267593 | G14: B8504ANODA_3 | H14: 17179_3 | I14: {=XLOOKUP(G14,KLUS!$A$2:$A$2010,KLUS!$E$2:$E$2010)+XLOOKUP(H14,KLUS!$A$2:$A$2010,KLUS!$E$2:$E$2010)} -> 64.4 | J14: =I14*(1-$J$2) -> 57.96 | K14: =J14*(1-$K$2) -> 46.368
... A104: PROFIL LED LIPOD 3m MLECZNA ANODOWANY HS 22 | B104: Towar | C104: 168,15 | E104: LIPOD-ALU-ML-3M | F104: 5905475360688 | G104: B5554ANODA_3 | H104: 17011_3 | I104: {=XLOOKUP(G104,KLUS!$A$2:$A$2010,KLUS!$E$2:$E$2010)+XLOOKUP(H104,KLUS!$A$2:$A$2010,KLUS!$E$2:$E$2010)} -> 190.9 | J104: =I104*(1-$J$2) -> 171.81 | K104: =J104*(1-$K$2) -> 137.448
A105: PROFIL LED LIPOD 3m MLECZNA ANODOWANY LI GER22 | B105: Towar | C105: 190,35 | E105: LIPOD-ALU-LIGER-3M | G105: B5554ANODA_3 | H105: 17032V1_3 | I105: {=XLOOKUP(G105,KLUS!$A$2:$A$2010,KLUS!$E$2:$E$2010)+XLOOKUP(H105,KLUS!$A$2:$A$2010,KLUS!$E$2:$E$2010)} -> 213.1 | J105: =I105*(1-$J$2) -> 191.79 | K105: =J105*(1-$K$2) -> 153.432
A106: Profil led LOC-30 1m anodowany z przesło ną przeźroczystą HS22 | B106: Towar | C106: 69,60 | E106: LOC-30-ALU-CL-1M-A | F106: 5903684853410 | G106: 18015ANODA_1 | H106: 17022_1 | I106: {=XLOOKUP(G106,KLUS!$A$2:$A$2010,KLUS!$E$2:$E$2010)+XLOOKUP(H106,KLUS!$A$2:$A$2010,KLUS!$E$2:$E$2010)} -> 79 | J106: =I106*(1-$J$2) -> 71.1 | K106: =J106*(1-$K$2) -> 56.88
A107: PROFIL LED LOC-30 1m MLECZNA ANODOWANY H S22 | B107: Towar | C107: 69,60 | E107: LOC-30-ALU-ML-1M-A | F107: 5903684853403 | G107: 18015ANODA_1 | H107: 17011_1 | I107: {=XLOOKUP(G107,KLUS!$A$2:$A$2010,KLUS!$E$2:$E$2010)+XLOOKUP(H107,KLUS!$A$2:$A$2010,KLUS!$E$2:$E$2010)} -> 79 | J107: =I107*(1-$J$2) -> 71.1 | K107: =J107*(1-$K$2) -> 56.88
A108: PROFIL LED LOC-30 2m MLECZNA ANODOWANY H S22 | B108: Towar | C108: 139,20 | E108: LOC-30-ALU-ML-2M-A | F108: 5905475360695 | G108: 18015ANODA_2 | H108: 17011_2 | I108: {=XLOOKUP(G108,KLUS!$A$2:$A$2010,KLUS!$E$2:$E$2010)+XLOOKUP(H108,KLUS!$A$2:$A$2010,KLUS!$E$2:$E$2010)} -> 158 | J108: =I108*(1-$J$2) -> 142.2 | K108: =J108*(1-$K$2) -> 113.76
A109: PROFIL LED LOC-30 2m PRZEŹROCZYSTA ANODO WANY HS22 | B109: Towar | C109: 139,20 | E109: LOC-30-ALU-CL-2M-A | F109: 5905475360701 | G109: 18015ANODA_2 | H109: 17022_2 | I109: {=XLOOKUP(G109,KLUS!$A$2:$A$2010,KLUS!$E$2:$E$2010)+XLOOKUP(H109,KLUS!$A$2:$A$2010,KLUS!$E$2:$E$2010)} -> 158 | J109: =I109*(1-$J$2) -> 142.2 | K109: =J109*(1-$K$2) -> 113.76
A110: PROFIL LED LOC-30 3m MLECZNA ANODOWANY H S22 | B110: Towar | C110: 208,80 | E110: LOC-30-ALU-ML-3M-A | F110: 5905475360718 | G110: 18015ANODA_3 | H110: 17011_3 | I110: {=XLOOKUP(G110,KLUS!$A$2:$A$2010,KLUS!$E$2:$E$2010)+XLOOKUP(H110,KLUS!$A$2:$A$2010,KLUS!$E$2:$E$2010)} -> 236.9 | J110: =I110*(1-$J$2) -> 213.21 | K110: =J110*(1-$K$2) -> 170.568
A111: PROFIL LED LOC-30 3m PRZEŹROCZYSTA ANODO WANY HS22 | B111: Towar | C111: 208,80 | E111: LOC-30-ALU-CL-3M-A | F111: 5905475360725 | G111: 18015ANODA_3 | H111: 17022_3 | I111: {=XLOOKUP(G111,KLUS!$A$2:$A$2010,KLUS!$E$2:$E$2010)+XLOOKUP(H111,KLUS!$A$2:$A$2010,KLUS!$E$2:$E$2010)} -> 236.9 | J111: =I111*(1-$J$2) -> 213.21 | K111: =J111*(1-$K$2) -> 170.568
A112: PROFIL LED LOKOM 1m MUN ANODOWANY | B112: Towar | C112: 61,65 | E112: LOKOM-ALU-MUN-1M | F112: 5905475360749 | G112: B5553ANODA_1 | H112: 17042_1 | I112: {=XLOOKUP(G112,KLUS!$A$2:$A$2010,KLUS!$E$2:$E$2010)+XLOOKUP(H112,KLUS!$A$2:$A$2010,KLUS!$E$2:$E$2010)} -> 68.8 | J112: =I112*(1-$J$2) -> 61.92 | K112: =J112*(1-$K$2) -> 49.536
A113: PROFIL LED LOKOM 1m PRZEŹROCZYSTA ANODOW ANY | B113: Towar | C113: 56,50 | E113: LOKOM-ALU-CL-1M | F113: 5905475360732 | G113: B5553ANODA_1 | H113: 17022_1 | I113: {=XLOOKUP(G113,KLUS!$A$2:$A$2010,KLUS!$E$2:$E$2010)+XLOOKUP(H113,KLUS!$A$2:$A$2010,KLUS!$E$2:$E$2010)} -> 63.6 | J113: =I113*(1-$J$2) -> 57.24 | K113: =J113*(1-$K$2) -> 45.792
A114: Profil led LOKOM 1m z przesłoną mleczną HS22 | B114: Towar | C114: 56,50 | E114: LOKOM-ALU-ML-1M | F114: 5903684853434 | G114: B5553ANODA_1 | H114: 17011_1 | I114: {=XLOOKUP(G114,KLUS!$A$2:$A$2010,KLUS!$E$2:$E$2010)+XLOOKUP(H114,KLUS!$A$2:$A$2010,KLUS!$E$2:$E$2010)} -> 63.6 | J114: =I114*(1-$J$2) -> 57.24 | K114: =J114*(1-$K$2) -> 45.792
A115: PROFIL LED LOKOM 2m MLECZNA ANODOWANY HS 22 | B115: Towar | C115: 113,00 | E115: LOKOM-ALU-ML-2M | F115: 5903684852475 | G115: B5553ANODA_2 | H115: 17011_2 | I115: {=XLOOKUP(G115,KLUS!$A$2:$A$2010,KLUS!$E$2:$E$2010)+XLOOKUP(H115,KLUS!$A$2:$A$2010,KLUS!$E$2:$E$2010)} -> 127.2 | J115: =I115*(1-$J$2) -> 114.48 | K115: =J115*(1-$K$2) -> 91.584
A116: PROFIL LED LOKOM 2m MUN ANODOWANY | B116: Towar | C116: 123,30 | E116: LOKOM-ALU-MUN-2M | F116: 5905475360756 | G116: B5553ANODA_2 | H116: 17042_2 | I116: {=XLOOKUP(G116,KLUS!$A$2:$A$2010,KLUS!$E$2:$E$2010)+XLOOKUP(H116,KLUS!$A$2:$A$2010,KLUS!$E$2:$E$2010)} -> 137.5 | J116: =I116*(1-$J$2) -> 123.75 | K116: =J116*(1-$K$2) -> 99
A117: PROFIL LED LOKOM 2m PRZEŹROCZYSTA ANODOW ANY | B117: Towar | C117: 113,00 | E117: LOKOM-ALU-CL-2M | F117: 5905475360763 | G117: B5553ANODA_2 | H117: 17022_2 | I117: {=XLOOKUP(G117,KLUS!$A$2:$A$2010,KLUS!$E$2:$E$2010)+XLOOKUP(H117,KLUS!$A$2:$A$2010,KLUS!$E$2:$E$2010)} -> 127.2 | J117: =I117*(1-$J$2) -> 114.48 | K117: =J117*(1-$K$2) -> 91.584
... A162: Profil led Micro 3m z osłoną przeźroczystą KA-COM | B162: Towar | C162: 40,50 | E162: MICRO-CLC-3M | F162: 5903684851591 | G162: B1888NA_3 | H162: 17122_3 | I162: {=XLOOKUP(G162,KLUS!$A$2:$A$2010,KLUS!$E$2:$E$2010)+XLOOKUP(H162,KLUS!$A$2:$A$2010,KLUS!$E$2:$E$2010)} -> 56.3 | J162: =I162*(1-$J$2) -> 50.67 | K162: =J162*(1-$K$2) -> 40.536
A163: Profil led Micro-K 1m anodowany z osłoną mleczną HS | B163: Towar | C163: 29,25 | E163: MICRO-K-ALU-ML-1M-HS | G163: B3775ANODA_1 | H163: 1369_1 | I163: {=XLOOKUP(G163,KLUS!$A$2:$A$2010,KLUS!$E$2:$E$2010)+XLOOKUP(H163,KLUS!$A$2:$A$2010,KLUS!$E$2:$E$2010)} -> #N/A | J163: =I163*(1-$J$2) -> #N/A | K163: =J163*(1-$K$2) -> #N/A
A164: Profil led Micro-K 1m anodowany z osłoną mleczną KA | B164: Produkt | C164: 21,00 | E164: MICRO-K-ALU-ML-1M | F164: 5901885266725 | G164: B3775ANODA_1 | H164: 17035_1 | I164: {=XLOOKUP(G164,KLUS!$A$2:$A$2010,KLUS!$E$2:$E$2010)+XLOOKUP(H164,KLUS!$A$2:$A$2010,KLUS!$E$2:$E$2010)} -> #N/A | J164: =I164*(1-$J$2) -> #N/A | K164: =J164*(1-$K$2) -> #N/A
A165: Profil led Micro-K 1m anodowany z osłoną mleczną KA-COM | B165: Produkt | C165: 22,25 | E165: MICRO-K-ALU-MLC-1M | F165: 5901885265704 | G165: B3775ANODA_1 | H165: 17179_1 | I165: {=XLOOKUP(G165,KLUS!$A$2:$A$2010,KLUS!$E$2:$E$2010)+XLOOKUP(H165,KLUS!$A$2:$A$2010,KLUS!$E$2:$E$2010)} -> #N/A | J165: =I165*(1-$J$2) -> #N/A | K165: =J165*(1-$K$2) -> #N/A
A166: Profil led Micro-K 1m anodowany z osłoną przeźroczystą KA | B166: Produkt | C166: 21,00 | E166: MICRO-K-ALU-CL-1M | F166: 5901885266770 | G166: B3775ANODA_1 | H166: 17036_1 | I166: {=XLOOKUP(G166,KLUS!$A$2:$A$2010,KLUS!$E$2:$E$2010)+XLOOKUP(H166,KLUS!$A$2:$A$2010,KLUS!$E$2:$E$2010)} -> #N/A | J166: =I166*(1-$J$2) -> #N/A | K166: =J166*(1-$K$2) -> #N/A
A167: Profil led Micro-K 1m anodowany z osłoną przeźroczystą KA-COM | B167: Towar | C167: 9,50 | E167: MICRO-K-ALU-CLC-1M | F167: 5901885265711 | G167: B3775ANODA_1 | H167: 17122_1 | I167: {=XLOOKUP(G167,KLUS!$A$2:$A$2010,KLUS!$E$2:$E$2010)+XLOOKUP(H167,KLUS!$A$2:$A$2010,KLUS!$E$2:$E$2010)} -> #N/A | J167: =I167*(1-$J$2) -> #N/A | K167: =J167*(1-$K$2) -> #N/A
A168: Profil led Micro-K 1m czarny anodowany | B168: Towar | C168: 14,15 | E168: MICRO-K-ALU-1M-CZ | F168: 5902280311621 | G168: B3775_K7_1 | I168: {=XLOOKUP(G168,KLUS!$A$2:$A$2010,KLUS!$E$2:$E$2010)+XLOOKUP(H168,KLUS!$A$2:$A$2010,KLUS!$E$2:$E$2010)} -> #N/A | J168: =I168*(1-$J$2) -> #N/A | K168: =J168*(1-$K$2) -> #N/A
A169: Profil led Micro-K 1m czarny anodowany z osłoną mleczną KA | B169: Towar | C169: 22,75 | E169: MICRO-K-ALU-ML-1M-CZ | F169: 5903684852390 | G169: B3775_K7_1 | H169: 17035_1 | I169: {=XLOOKUP(G169,KLUS!$A$2:$A$2010,KLUS!$E$2:$E$2010)+XLOOKUP(H169,KLUS!$A$2:$A$2010,KLUS!$E$2:$E$2010)} -> #N/A | J169: =I169*(1-$J$2) -> #N/A | K169: =J169*(1-$K$2) -> #N/A
A170: Profil led Micro-K 2m anodowany wyc | B170: Towar | C170: 34,40 | E170: MICRO-K-ALU-2M | F170: 5906660780144 | G170: B3775ANODA_2 | I170: {=XLOOKUP(G170,KLUS!$A$2:$A$2010,KLUS!$E$2:$E$2010)+XLOOKUP(H170,KLUS!$A$2:$A$2010,KLUS!$E$2:$E$2010)} -> #N/A | J170: =I170*(1-$J$2) -> #N/A | K170: =J170*(1-$K$2) -> #N/A
A171: Profil led Micro-K 2m anodowany z osłoną mleczną HS | B171: Towar | C171: 58,50 | E171: MICRO-K-ALU-ML-2M-HS | G171: B3775_2 | H171: 1369_2 | I171: {=XLOOKUP(G171,KLUS!$A$2:$A$2010,KLUS!$E$2:$E$2010)+XLOOKUP(H171,KLUS!$A$2:$A$2010,KLUS!$E$2:$E$2010)} -> #N/A | J171: =I171*(1-$J$2) -> #N/A | K171: =J171*(1-$K$2) -> #N/A
A172: Profil led Micro-K 2m anodowany z osłoną mleczną KA | B172: Towar | C172: 55,90 | E172: MICRO-K-ALU-ML-2M | F172: 5901885266015 | G172: B3775ANODA_2 | H172: 17035_2 | I172: {=XLOOKUP(G172,KLUS!$A$2:$A$2010,KLUS!$E$2:$E$2010)+XLOOKUP(H172,KLUS!$A$2:$A$2010,KLUS!$E$2:$E$2010)} -> #N/A | J172: =I172*(1-$J$2) -> #N/A | K172: =J172*(1-$K$2) -> #N/A
A173: Profil led Micro-K 2m anodowany z osłoną mleczną KA-COM | B173: Produkt | C173: 44,50 | E173: MICRO-K-ALU-MLC-2M | F173: 5901885265728 | G173: B3775ANODA_2 | H173: 17179_2 | I173: {=XLOOKUP(G173,KLUS!$A$2:$A$2010,KLUS!$E$2:$E$2010)+XLOOKUP(H173,KLUS!$A$2:$A$2010,KLUS!$E$2:$E$2010)} -> #N/A | J173: =I173*(1-$J$2) -> #N/A | K173: =J173*(1-$K$2) -> #N/A
...

Sheet roboczykarol
A1: Nazwa cała | B1: R | C1: Cena sprzedaży netto | D1: Nr katalogowy | E1: Indeks handlowy | F1: Kod kreskowy | G1: Indeks producenta | H1: Indeks producenta | I1: Cena hurt Klus | J1: Detal netto | K1: Hurt netto | L1: detal netto | M1: detal brutto | N1: Hurt netto | O1: Hurt brutto | P1: kpl detal netto | Q1: kpl detal brutto | R1: kpl hurt netto | S1: kpl hurt brutto
C2: PRESCOT WFMAG | D2: PRESCOT | E2: PRESCOT | F2: PRESCOT | G2: Profil | H2: Osłona | J2: 0.1 | K2: 0.2 | P2: 0 | Q2: 0 | R2: -0.2 | S2: -0.2
A3: Profil led 45-16 1m anodowany z osłoną mleczną KA | B3: Towar | C3: 27,30 | D3: 42817 | E3: 45-16-ML-1M-A | F3: 5903684850167 | G3: B8504ANODA_1 | H3: 17035_1 | I3: {=XLOOKUP(G3,KLUS!$A$2:$A$2010,KLUS!$E$2:$E$2010)+XLOOKUP(H3,KLUS!$A$2:$A$2010,KLUS!$E$2:$E$2010)} -> 27.3 | J3: =I3*(1-$J$2) -> 24.57 | K3: =J3*(1-$K$2) -> 19.656 | L3: =ROUND(M3/1.23,100) -> 24.552846 | M3: =ROUND(J3*1.23,1) -> 30.2 | N3: =round(L3*0.8,1) -> 19.6 | O3: =round(N3*1.23,100) -> 24.108
A4: Profil led 45-16 1m anodowany z osłoną mleczną KA-COM | B4: Towar | C4: 21,50 | D4: 42817 | E4: 45-16-MLC-1M-A | F4: 5901885267586 | G4: B8504ANODA_1 | H4: 17179_1 | I4: {=XLOOKUP(G4,KLUS!$A$2:$A$2010,KLUS!$E$2:$E$2010)+XLOOKUP(H4,KLUS!$A$2:$A$2010,KLUS!$E$2:$E$2010)} -> 21.5 | J4: =I4*(1-$J$2) -> 19.35 | K4: =J4*(1-$K$2) -> 15.48 | L4: =ROUND(M4/1.23,100) -> 19.349594 | M4: =ROUND(J4*1.23,1) -> 23.8 | N4: =round(L4*0.8,1) -> 15.5 | O4: =round(N4*1.23,100) -> 19.065
A5: Profil led 45-16 1m anodowany z osłoną mleczną LIGER | B5: Towar | C5: 30,95 | D5: 42907 | E5: 45-16-ML-1M-A-L | F5: 5905475360442 | G5: B8504ANODA_1 | H5: 17037_1 | I5: {=XLOOKUP(G5,KLUS!$A$2:$A$2010,KLUS!$E$2:$E$2010)+XLOOKUP(H5,KLUS!$A$2:$A$2010,KLUS!$E$2:$E$2010)} -> 33.7 | J5: =I5*(1-$J$2) -> 30.33 | K5: =J5*(1-$K$2) -> 24.264 | L5: =ROUND(M5/1.23,100) -> 30.325203 | M5: =ROUND(J5*1.23,1) -> 37.3 | N5: =round(L5*0.8,1) -> 24.3 | O5: =round(N5*1.23,100) -> 29.889
A6: Profil led 45-16 1m anodowany z osłoną przeźroczystą KA | B6: Towar | C6: 24,50 | D6: 42907 | E6: 45-16-CL-1M-A | F6: 5903684850174 | G6: B8504ANODA_1 | H6: 17036_1 | I6: {=XLOOKUP(G6,KLUS!$A$2:$A$2010,KLUS!$E$2:$E$2010)+XLOOKUP(H6,KLUS!$A$2:$A$2010,KLUS!$E$2:$E$2010)} -> 27.3 | J6: =I6*(1-$J$2) -> 24.57 | K6: =J6*(1-$K$2) -> 19.656 | L6: =ROUND(M6/1.23,100) -> 24.552846 | M6: =ROUND(J6*1.23,1) -> 30.2 | N6: =round(L6*0.8,1) -> 19.6 | O6: =round(N6*1.23,100) -> 24.108
A7: Profil led 45-16 1m anodowany z osłoną przeźroczystą KA-COM | B7: Towar | C7: 18,80 | D7: 42909 | E7: 45-16-CLC-1M-A | F7: 5903684850181 | G7: B8504ANODA_1 | H7: 17122_1 | I7: {=XLOOKUP(G7,KLUS!$A$2:$A$2010,KLUS!$E$2:$E$2010)+XLOOKUP(H7,KLUS!$A$2:$A$2010,KLUS!$E$2:$E$2010)} -> 21.5 | J7: =I7*(1-$J$2) -> 19.35 | K7: =J7*(1-$K$2) -> 15.48 | L7: =ROUND(M7/1.23,100) -> 19.349594 | M7: =ROUND(J7*1.23,1) -> 23.8 | N7: =round(L7*0.8,1) -> 15.5 | O7: =round(N7*1.23,100) -> 19.065
A8: Profil led 45-16 2m anodowany z osłoną mleczną KA | B8: Towar | C8: 35,00 | D8: 42909 | E8: 45-16-ML-2M-A | F8: 5903684850198 | G8: B8504ANODA_2 | H8: 17035_2 | I8: {=XLOOKUP(G8,KLUS!$A$2:$A$2010,KLUS!$E$2:$E$2010)+XLOOKUP(H8,KLUS!$A$2:$A$2010,KLUS!$E$2:$E$2010)} -> 54.5 | J8: =I8*(1-$J$2) -> 49.05 | K8: =J8*(1-$K$2) -> 39.24 | L8: =ROUND(M8/1.23,100) -> 49.02439 | M8: =ROUND(J8*1.23,1) -> 60.3 | N8: =round(L8*0.8,1) -> 39.2 | O8: =round(N8*1.23,100) -> 48.216
A9: Profil led 45-16 2m anodowany z osłoną mleczną KA-COM | B9: Produkt | C9: 30,00 | E9: 45-16-MLC-2M-A | F9: 5901885267357 | G9: B8504ANODA_2 | H9: 17179_2 | I9: {=XLOOKUP(G9,KLUS!$A$2:$A$2010,KLUS!$E$2:$E$2010)+XLOOKUP(H9,KLUS!$A$2:$A$2010,KLUS!$E$2:$E$2010)} -> 43 | J9: =I9*(1-$J$2) -> 38.7 | K9: =J9*(1-$K$2) -> 30.96 | L9: =ROUND(M9/1.23,100) -> 38.699187 | M9: =ROUND(J9*1.23,1) -> 47.6 | N9: =round(L9*0.8,1) -> 31 | O9: =round(N9*1.23,100) -> 38.13
A10: Profil led 45-16 2m anodowany z osłoną mleczną LIGER | B10: Towar | C10: 61,90 | D10: 342 | E10: 45-16-ML-2M-A-L | F10: 5905475360459 | G10: B8504ANODA_2 | H10: 17037_2 | I10: {=XLOOKUP(G10,KLUS!$A$2:$A$2010,KLUS!$E$2:$E$2010)+XLOOKUP(H10,KLUS!$A$2:$A$2010,KLUS!$E$2:$E$2010)} -> 67.4 | J10: =I10*(1-$J$2) -> 60.66 | K10: =J10*(1-$K$2) -> 48.528 | L10: =ROUND(M10/1.23,100) -> 60.650407 | M10: =ROUND(J10*1.23,1) -> 74.6 | N10: =round(L10*0.8,1) -> 48.5 | O10: =round(N10*1.23,100) -> 59.655
A11: Profil led 45-16 2m anodowany z osłoną przeźroczystą KA | B11: Towar | C11: 49,00 | E11: 45-16-CL-2M-A | F11: 5903684850204 | G11: B8504ANODA_2 | H11: 17036_2 | I11: {=XLOOKUP(G11,KLUS!$A$2:$A$2010,KLUS!$E$2:$E$2010)+XLOOKUP(H11,KLUS!$A$2:$A$2010,KLUS!$E$2:$E$2010)} -> 54.5 | J11: =I11*(1-$J$2) -> 49.05 | K11: =J11*(1-$K$2) -> 39.24 | L11: =ROUND(M11/1.23,100) -> 49.02439 | M11: =ROUND(J11*1.23,1) -> 60.3 | N11: =round(L11*0.8,1) -> 39.2 | O11: =round(N11*1.23,100) -> 48.216
A12: Profil led 45-16 2m anodowany z osłoną przeźroczystą KA-COM | B12: Towar | C12: 37,60 | E12: 45-16-CLC-2M-A | F12: 5901885267364 | G12: B8504ANODA_2 | H12: 17122_2 | I12: {=XLOOKUP(G12,KLUS!$A$2:$A$2010,KLUS!$E$2:$E$2010)+XLOOKUP(H12,KLUS!$A$2:$A$2010,KLUS!$E$2:$E$2010)} -> 43 | J12: =I12*(1-$J$2) -> 38.7 | K12: =J12*(1-$K$2) -> 30.96 | L12: =ROUND(M12/1.23,100) -> 38.699187 | M12: =ROUND(J12*1.23,1) -> 47.6 | N12: =round(L12*0.8,1) -> 31 | O12: =round(N12*1.23,100) -> 38.13
A13: Profil led 45-16 3m anodowany z osłoną mleczną KA | B13: Towar | C13: 73,50 | E13: 45-16-ML-3M-A | F13: 5903684850211 | G13: B8504ANODA_3 | H13: 17035_3 | I13: {=XLOOKUP(G13,KLUS!$A$2:$A$2010,KLUS!$E$2:$E$2010)+XLOOKUP(H13,KLUS!$A$2:$A$2010,KLUS!$E$2:$E$2010)} -> 81.7 | J13: =I13*(1-$J$2) -> 73.53 | K13: =J13*(1-$K$2) -> 58.824 | L13: =ROUND(M13/1.23,100) -> 73.495935 | M13: =ROUND(J13*1.23,1) -> 90.4 | N13: =round(L13*0.8,1) -> 58.8 | O13: =round(N13*1.23,100) -> 72.324
A14: Profil led 45-16 3m anodowany z osłoną mleczną KA-COM | B14: Towar | C14: 56,40 | E14: 45-16-MLC-3M-A | F14: 5901885267593 | G14: B8504ANODA_3 | H14: 17179_3 | I14: {=XLOOKUP(G14,KLUS!$A$2:$A$2010,KLUS!$E$2:$E$2010)+XLOOKUP(H14,KLUS!$A$2:$A$2010,KLUS!$E$2:$E$2010)} -> 64.4 | J14: =I14*(1-$J$2) -> 57.96 | K14: =J14*(1-$K$2) -> 46.368 | L14: =ROUND(M14/1.23,100) -> 57.96748 | M14: =ROUND(J14*1.23,1) -> 71.3 | N14: =round(L14*0.8,1) -> 46.4 | O14: =round(N14*1.23,100) -> 57.072
A15: Profil led 45-16 3m anodowany z osłoną mleczną LIGER | B15: Towar | C15: 92,85 | E15: 45-16-ML-3M-A-L | F15: 5905475360466 | G15: B8504ANODA_3 | H15: 17037_3 | I15: {=XLOOKUP(G15,KLUS!$A$2:$A$2010,KLUS!$E$2:$E$2010)+XLOOKUP(H15,KLUS!$A$2:$A$2010,KLUS!$E$2:$E$2010)} -> 101 | J15: =I15*(1-$J$2) -> 90.9 | K15: =J15*(1-$K$2) -> 72.72 | L15: =ROUND(M15/1.23,100) -> 90.894309 | M15: =ROUND(J15*1.23,1) -> 111.8 | N15: =round(L15*0.8,1) -> 72.7 | O15: =round(N15*1.23,100) -> 89.421
A16: Profil led 45-16 3m anodowany z osłoną przeźroczystą KA | B16: Towar | C16: 73,50 | E16: 45-16-CL-3M-A | F16: 5903684850228 | G16: B8504ANODA_3 | H16: 17036_3 | I16: {=XLOOKUP(G16,KLUS!$A$2:$A$2010,KLUS!$E$2:$E$2010)+XLOOKUP(H16,KLUS!$A$2:$A$2010,KLUS!$E$2:$E$2010)} -> 81.7 | J16: =I16*(1-$J$2) -> 73.53 | K16: =J16*(1-$K$2) -> 58.824 | M16: =ROUND(J16*1.23,1) -> 90.4 | N16: =round(L16*0.8,1) -> 0 | O16: =round(N16*1.23,100) -> 0
A17: Profil led 45-16 3m anodowany z osłoną przeźroczystą KA-COM | B17: Towar | C17: 56,40 | E17: 45-16-CLC-3M-A | F17: 5903684850235 | G17: B8504ANODA_3 | H17: 17122_3 | I17: {=XLOOKUP(G17,KLUS!$A$2:$A$2010,KLUS!$E$2:$E$2010)+XLOOKUP(H17,KLUS!$A$2:$A$2010,KLUS!$E$2:$E$2010)} -> 64.4 | J17: =I17*(1-$J$2) -> 57.96 | K17: =J17*(1-$K$2) -> 46.368 | M17: =ROUND(J17*1.23,1) -> 71.3 | N17: =round(L17*0.8,1) -> 0
A18: Profil led 45-ALU 1m anodowany z osłoną mleczną KA | B18: Towar | C18: 33,25 | E18: 45-ALU-ML-1M-A | F18: 5902596558376 | G18: B4023ANODA_1 | H18: 17035_1 | I18: {=XLOOKUP(G18,KLUS!$A$2:$A$2010,KLUS!$E$2:$E$2010)+XLOOKUP(H18,KLUS!$A$2:$A$2010,KLUS!$E$2:$E$2010)} -> 35.6 | J18: =I18*(1-$J$2) -> 32.04 | K18: =J18*(1-$K$2) -> 25.632 | M18: =ROUND(J18*1.23,1) -> 39.4 | N18: =round(L18*0.8,1) -> 0
A19: Profil led 45-ALU 1m anodowany z osłoną mleczną KA-COM | B19: Towar | C19: 24,75 | E19: 45-ALU-MLC-1M-A | F19: 5901885266121 | G19: B4023ANODA_1 | H19: 17179_1 | I19: {=XLOOKUP(G19,KLUS!$A$2:$A$2010,KLUS!$E$2:$E$2010)+XLOOKUP(H19,KLUS!$A$2:$A$2010,KLUS!$E$2:$E$2010)} -> 29.8 | J19: =I19*(1-$J$2) -> 26.82 | K19: =J19*(1-$K$2) -> 21.456 | M19: =ROUND(J19*1.23,1) -> 33 | N19: =round(L19*0.8,1) -> 0
A20: Profil led 45-ALU 1m anodowany z osłoną przeźroczystą KA | B20: Towar | C20: 33,25 | E20: 45-ALU-CL-1M-A | F20: 5903684850280 | G20: B4023ANODA_1 | H20: 17036_1 | I20: {=XLOOKUP(G20,KLUS!$A$2:$A$2010,KLUS!$E$2:$E$2010)+XLOOKUP(H20,KLUS!$A$2:$A$2010,KLUS!$E$2:$E$2010)} -> 35.6 | J20: =I20*(1-$J$2) -> 32.04 | K20: =J20*(1-$K$2) -> 25.632 | M20: =ROUND(J20*1.23,1) -> 39.4 | N20: =round(L20*0.8,1) -> 0
A21: Profil led 45-ALU 1m anodowany z osłoną przeźroczystą KA-COM | B21: Towar | C21: 24,75 | E21: 45-ALU-CLC-1M-A | F21: 5903684850303 | G21: B4023ANODA_1 | H21: 17122_1 | I21: {=XLOOKUP(G21,KLUS!$A$2:$A$2010,KLUS!$E$2:$E$2010)+XLOOKUP(H21,KLUS!$A$2:$A$2010,KLUS!$E$2:$E$2010)} -> 29.8 | J21: =I21*(1-$J$2) -> 26.82 | K21: =J21*(1-$K$2) -> 21.456 | M21: =ROUND(J21*1.23,1) -> 33 | N21: =round(L21*0.8,1) -> 0
A22: Profil led 45-ALU 1m biały lakierowany z osłoną mleczną KA | B22: Produkt | C22: 35,00 | E22: 45-ALU-ML-1M-B | F22: 5903684850266 | G22: B4023L9010OD_1 | H22: 17035_1 | I22: {=XLOOKUP(G22,KLUS!$A$2:$A$2010,KLUS!$E$2:$E$2010)+XLOOKUP(H22,KLUS!$A$2:$A$2010,KLUS!$E$2:$E$2010)} -> 56.4 | J22: =I22*(1-$J$2) -> 50.76 | K22: =J22*(1-$K$2) -> 40.608 | M22: =ROUND(J22*1.23,1) -> 62.4 | N22: =round(L22*0.8,1) -> 0
A23: Profil led 45-ALU 1m czarny anodowany z osłoną mleczną KA | B23: Towar | C23: 0,00 | E23: 45-ALU-ML-1M-A-CZ | F23: 5903684850259 | G23: B4023K7_1 | H23: 17035_1 | I23: {=XLOOKUP(G23,KLUS!$A$2:$A$2010,KLUS!$E$2:$E$2010)+XLOOKUP(H23,KLUS!$A$2:$A$2010,KLUS!$E$2:$E$2010)} -> 39.7 | J23: =I23*(1-$J$2) -> 35.73 | K23: =J23*(1-$K$2) -> 28.584 | M23: =ROUND(J23*1.23,1) -> 43.9 | N23: =round(L23*0.8,1) -> 0
A24: Profil led 45-ALU 1m z osłoną mleczną KA | B24: Towar | C24: 30,45 | E24: 45-ALU-ML-1M | F24: 5903684850242 | G24: B4023NA_1 | H24: 17035_1 | I24: {=XLOOKUP(G24,KLUS!$A$2:$A$2010,KLUS!$E$2:$E$2010)+XLOOKUP(H24,KLUS!$A$2:$A$2010,KLUS!$E$2:$E$2010)} -> 32.5 | J24: =I24*(1-$J$2) -> 29.25 | K24: =J24*(1-$K$2) -> 23.4 | M24: =ROUND(J24*1.23,1) -> 36
A25: Profil led 45-ALU 1m z osłoną mleczną KA-COM | B25: Towar | C25: 24,75 | E25: 45-ALU-MLC-1M | F25: 5901885266114 | G25: B4023NA_1 | H25: 17179_1 | I25: {=XLOOKUP(G25,KLUS!$A$2:$A$2010,KLUS!$E$2:$E$2010)+XLOOKUP(H25,KLUS!$A$2:$A$2010,KLUS!$E$2:$E$2010)} -> 26.7 | J25: =I25*(1-$J$2) -> 24.03 | K25: =J25*(1-$K$2) -> 19.224 | M25: =ROUND(J25*1.23,1) -> 29.6
A26: Profil led 45-ALU 1m z osłoną przeźroczystą KA | B26: Towar | C26: 30,45 | E26: 45-ALU-CL-1M | F26: 5901885269757 | G26: B4023NA_1 | H26: 17036_1 | I26: {=XLOOKUP(G26,KLUS!$A$2:$A$2010,KLUS!$E$2:$E$2010)+XLOOKUP(H26,KLUS!$A$2:$A$2010,KLUS!$E$2:$E$2010)} -> 32.5 | J26: =I26*(1-$J$2) -> 29.25 | K26: =J26*(1-$K$2) -> 23.4 | M26: =ROUND(J26*1.23,1) -> 36
A27: Profil led 45-ALU 1m z osłoną przeźroczystą KA-COM | B27: Towar | C27: 29,80 | E27: 45-ALU-CLC-1M | F27: 5903684850297 | G27: B4023NA_1 | H27: 17122_1 | I27: {=XLOOKUP(G27,KLUS!$A$2:$A$2010,KLUS!$E$2:$E$2010)+XLOOKUP(H27,KLUS!$A$2:$A$2010,KLUS!$E$2:$E$2010)} -> 26.7 | J27: =I27*(1-$J$2) -> 24.03 | K27: =J27*(1-$K$2) -> 19.224 | M27: =ROUND(J27*1.23,1) -> 29.6
A28: Profil led 45-ALU 2m anodowany z osłoną mleczną KA | B28: Produkt | C28: 66,50 | E28: 45-ALU-ML-2M-A | F28: 5902596558383 | G28: B4023ANODA_2 | H28: 17035_2 | I28: {=XLOOKUP(G28,KLUS!$A$2:$A$2010,KLUS!$E$2:$E$2010)+XLOOKUP(H28,KLUS!$A$2:$A$2010,KLUS!$E$2:$E$2010)} -> 71.2 | J28: =I28*(1-$J$2) -> 64.08 | K28: =J28*(1-$K$2) -> 51.264 | M28: =ROUND(J28*1.23,1) -> 78.8
A29: Profil led 45-ALU 2m anodowany z osłoną mleczną KA-COM | B29: Produkt | C29: 55,10 | E29: 45-ALU-MLC-2M-A | F29: 5901885266022 | G29: B4023ANODA_2 | H29: 17179_2 | I29: {=XLOOKUP(G29,KLUS!$A$2:$A$2010,KLUS!$E$2:$E$2010)+XLOOKUP(H29,KLUS!$A$2:$A$2010,KLUS!$E$2:$E$2010)} -> 59.7 | J29: =I29*(1-$J$2) -> 53.73 | K29: =J29*(1-$K$2) -> 42.984 | M29: =ROUND(J29*1.23,1) -> 66.1
A30: Profil led 45-ALU 2m anodowany z osłoną przeźroczystą KA | B30: Towar | C30: 66,50 | E30: 45-ALU-CL-2M-A | F30: 5905475360473 | G30: B4023ANODA_2 | H30: 17036_2 | I30: {=XLOOKUP(G30,KLUS!$A$2:$A$2010,KLUS!$E$2:$E$2010)+XLOOKUP(H30,KLUS!$A$2:$A$2010,KLUS!$E$2:$E$2010)} -> 71.2 | J30: =I30*(1-$J$2) -> 64.08 | K30: =J30*(1-$K$2) -> 51.264 | M30: =ROUND(J30*1.23,1) -> 78.8
A31: Profil led 45-ALU 2m anodowany z osłoną przeźroczystą KA-COM | B31: Produkt | C31: 55,10 | E31: 45-ALU-CLC-2M-A | F31: 5901885265797 | G31: B4023ANODA_2 | H31: 17122_2 | I31: {=XLOOKUP(G31,KLUS!$A$2:$A$2010,KLUS!$E$2:$E$2010)+XLOOKUP(H31,KLUS!$A$2:$A$2010,KLUS!$E$2:$E$2010)} -> 59.7 | J31: =I31*(1-$J$2) -> 53.73 | K31: =J31*(1-$K$2) -> 42.984
A32: Profil led 45-ALU 2m biały lakierowany z osłoną mleczną KA | B32: Towar | C32: 0,00 | E32: 45-ALU-ML-2M-B | F32: 5905475360480 | G32: B4023L9010OD_2 | H32: 17035_2 | I32: {=XLOOKUP(G32,KLUS!$A$2:$A$2010,KLUS!$E$2:$E$2010)+XLOOKUP(H32,KLUS!$A$2:$A$2010,KLUS!$E$2:$E$2010)} -> 112.6 | J32: =I32*(1-$J$2) -> 101.34 | K32: =J32*(1-$K$2) -> 81.072
A33: Profil led 45-ALU 2m biały lakierowany z osłoną mleczną KA-COM | B33: Towar | C33: 92,50 | E33: 45-ALU-MLC-2M-B | F33: 5903684850426 | G33: B4023L9010OD_2 | H33: 17179_2 | I33: {=XLOOKUP(G33,KLUS!$A$2:$A$2010,KLUS!$E$2:$E$2010)+XLOOKUP(H33,KLUS!$A$2:$A$2010,KLUS!$E$2:$E$2010)} -> 101.1 | J33: =I33*(1-$J$2) -> 90.99 | K33: =J33*(1-$K$2) -> 72.792
A34: Profil led 45-ALU 2m czarny anodowany z osłoną mleczną KA | B34: Towar | C34: 0,00 | E34: 45-ALU-ML-2M-A-CZ | F34: 5905475360497 | G34: B4023K7_2 | H34: 17035_2 | I34: {=XLOOKUP(G34,KLUS!$A$2:$A$2010,KLUS!$E$2:$E$2010)+XLOOKUP(H34,KLUS!$A$2:$A$2010,KLUS!$E$2:$E$2010)} -> 79.3 | J34: =I34*(1-$J$2) -> 71.37 | K34: =J34*(1-$K$2) -> 57.096
A35: Profil led 45-ALU 2m z osłoną mleczną KA | B35: Towar | C35: 60,90 | E35: 45-ALU-ML-2M | F35: 5901885266107 | G35: B4023NA_2 | H35: 17035_2 | I35: {=XLOOKUP(G35,KLUS!$A$2:$A$2010,KLUS!$E$2:$E$2010)+XLOOKUP(H35,KLUS!$A$2:$A$2010,KLUS!$E$2:$E$2010)} -> 64.9 | J35: =I35*(1-$J$2) -> 58.41 | K35: =J35*(1-$K$2) -> 46.728
A36: Profil led 45-ALU 2m z osłoną mleczną KA-COM | B36: Produkt | C36: 49,50 | E36: 45-ALU-MLC-2M | F36: 5901885266039 | G36: B4023NA_2 | H36: 17179_2 | I36: {=XLOOKUP(G36,KLUS!$A$2:$A$2010,KLUS!$E$2:$E$2010)+XLOOKUP(H36,KLUS!$A$2:$A$2010,KLUS!$E$2:$E$2010)} -> 53.4 | J36: =I36*(1-$J$2) -> 48.06 | K36: =J36*(1-$K$2) -> 38.448
A37: Profil led 45-ALU 2m z osłoną przeźroczystą KA | B37: Towar | C37: 60,90 | E37: 45-ALU-CL-2M | F37: 5905475360510 | G37: B4023NA_2 | H37: 17036_2 | I37: {=XLOOKUP(G37,KLUS!$A$2:$A$2010,KLUS!$E$2:$E$2010)+XLOOKUP(H37,KLUS!$A$2:$A$2010,KLUS!$E$2:$E$2010)} -> 64.9 | J37: =I37*(1-$J$2) -> 58.41 | K37: =J37*(1-$K$2) -> 46.728
A38: Profil led 45-ALU 2m z osłoną przeźroczystą KA-COM | B38: Produkt | C38: 49,50 | E38: 45-ALU-CLC-2M | F38: 5901885269764 | G38: B4023NA_2 | H38: 17122_2 | I38: {=XLOOKUP(G38,KLUS!$A$2:$A$2010,KLUS!$E$2:$E$2010)+XLOOKUP(H38,KLUS!$A$2:$A$2010,KLUS!$E$2:$E$2010)} -> 53.4 | J38: =I38*(1-$J$2) -> 48.06 | K38: =J38*(1-$K$2) -> 38.448
A39: Profil led 45-ALU 3m anodowany z osłoną mleczną KA | B39: Towar | C39: 99,75 | E39: 45-ALU-ML-3M-A | F39: 5905475360527 | G39: B4023ANODA_3 | H39: 17035_3 | I39: {=XLOOKUP(G39,KLUS!$A$2:$A$2010,KLUS!$E$2:$E$2010)+XLOOKUP(H39,KLUS!$A$2:$A$2010,KLUS!$E$2:$E$2010)} -> 106.8 | J39: =I39*(1-$J$2) -> 96.12 | K39: =J39*(1-$K$2) -> 76.896
A40: Profil led 45-ALU 3m anodowany z osłoną mleczną KA-COM | B40: Towar | C40: 82,65 | E40: 45-ALU-MLC-3M-A | F40: 5903684853069 | G40: B4023ANODA_3 | H40: 17179_3 | I40: {=XLOOKUP(G40,KLUS!$A$2:$A$2010,KLUS!$E$2:$E$2010)+XLOOKUP(H40,KLUS!$A$2:$A$2010,KLUS!$E$2:$E$2010)} -> 89.5 | J40: =I40*(1-$J$2) -> 80.55 | K40: =J40*(1-$K$2) -> 64.44
...

Sheet DO WGRANIA
A1: Artykuł | B1: Nr katalogowy | C1: VAT zakupu | D1: Waluta zakupu | E1: Cena zakupu netto | F1: Cena zakupu brutto | G1: IdCeny | H1: Cena | I1: Netto | J1: Brutto | K1: Tryb | L1: VAT sprzedaży | M1: Waluta sprzedaży
A2: Kształtka Kozel L90 z osłoną mleczną HS-22 | B2: 42817 | G2: 2 | H2: Hurtowa | I2: {=IFS(H2="detaliczna",XLOOKUP(B2,roboczykarol!$D$3:$D$2010,roboczykarol!$L$3:$L$2010),H2="Hurtowa",XLOOKUP(B2,roboczykarol!$D$3:$D$2010,roboczykarol!$N$3:$N$2010))} -> 19.6 | J2: {=IFS(H2="Hurtowa",XLOOKUP(B2,roboczykarol!$D$3:$D$2010,roboczykarol!$O$3:$O$2010),H2="Detaliczna",round(XLOOKUP(B2,roboczykarol!$D$3:$D$2010,roboczykarol!$M$3:$M$2010),1))} -> 24.108 | K2: netto | L2: 23
A3: Kształtka Kozel L90 z osłoną mleczną HS-22 | B3: 42817 | G3: 1 | H3: Detaliczna | I3: {=IFS(H3="detaliczna",XLOOKUP(B3,roboczykarol!$D$3:$D$2010,roboczykarol!$L$3:$L$2010),H3="Hurtowa",XLOOKUP(B3,roboczykarol!$D$3:$D$2010,roboczykarol!$N$3:$N$2010))} -> 24.552846 | J3: {=IFS(H3="Hurtowa",XLOOKUP(B3,roboczykarol!$D$3:$D$2010,roboczykarol!$O$3:$O$2010),H3="Detaliczna",round(XLOOKUP(B3,roboczykarol!$D$3:$D$2010,roboczykarol!$M$3:$M$2010),1))} -> 30.2 | K3: netto | L3: 23
A4: Kształtka Kozel L90 z osłoną mleczną LIGER-22 | B4: 42907 | G4: 2 | H4: Hurtowa | I4: {=IFS(H4="detaliczna",XLOOKUP(B4,roboczykarol!$D$3:$D$2010,roboczykarol!$L$3:$L$2010),H4="Hurtowa",XLOOKUP(B4,roboczykarol!$D$3:$D$2010,roboczykarol!$N$3:$N$2010))} -> 24.3 | J4: {=IFS(H4="Hurtowa",XLOOKUP(B4,roboczykarol!$D$3:$D$2010,roboczykarol!$O$3:$O$2010),H4="Detaliczna",round(XLOOKUP(B4,roboczykarol!$D$3:$D$2010,roboczykarol!$M$3:$M$2010),1))} -> 29.889 | K4: netto | L4: 23
A5: Kształtka Kozel L90 z osłoną mleczną LIGER-22 | B5: 42907 | G5: 1 | H5: Detaliczna | I5: {=IFS(H5="detaliczna",XLOOKUP(B5,roboczykarol!$D$3:$D$2010,roboczykarol!$L$3:$L$2010),H5="Hurtowa",XLOOKUP(B5,roboczykarol!$D$3:$D$2010,roboczykarol!$N$3:$N$2010))} -> 30.325203 | J5: {=IFS(H5="Hurtowa",XLOOKUP(B5,roboczykarol!$D$3:$D$2010,roboczykarol!$O$3:$O$2010),H5="Detaliczna",round(XLOOKUP(B5,roboczykarol!$D$3:$D$2010,roboczykarol!$M$3:$M$2010),1))} -> 37.3 | K5: netto | L5: 23
A6: Kształtka Kozel L90PW z osłoną mleczną LIGER-22 | B6: 42909 | G6: 2 | H6: Hurtowa | I6: {=IFS(H6="detaliczna",XLOOKUP(B6,roboczykarol!$D$3:$D$2010,roboczykarol!$L$3:$L$2010),H6="Hurtowa",XLOOKUP(B6,roboczykarol!$D$3:$D$2010,roboczykarol!$N$3:$N$2010))} -> 15.5 | J6: {=IFS(H6="Hurtowa",XLOOKUP(B6,roboczykarol!$D$3:$D$2010,roboczykarol!$O$3:$O$2010),H6="Detaliczna",round(XLOOKUP(B6,roboczykarol!$D$3:$D$2010,roboczykarol!$M$3:$M$2010),1))} -> 19.065 | K6: netto | L6: 23
A7: Kształtka Kozel L90PW z osłoną mleczną LIGER-22 | B7: 42909 | G7: 1 | H7: Detaliczna | I7: {=IFS(H7="detaliczna",XLOOKUP(B7,roboczykarol!$D$3:$D$2010,roboczykarol!$L$3:$L$2010),H7="Hurtowa",XLOOKUP(B7,roboczykarol!$D$3:$D$2010,roboczykarol!$N$3:$N$2010))} -> 19.349594 | J7: {=IFS(H7="Hurtowa",XLOOKUP(B7,roboczykarol!$D$3:$D$2010,roboczykarol!$O$3:$O$2010),H7="Detaliczna",round(XLOOKUP(B7,roboczykarol!$D$3:$D$2010,roboczykarol!$M$3:$M$2010),1))} -> 23.8 | K7: netto | L7: 23
A8: Kształtka Kozel L90PZ z osłoną mleczną LIGER-22 | B8: 342 | G8: 2 | H8: Hurtowa | I8: {=IFS(H8="detaliczna",XLOOKUP(B8,roboczykarol!$D$3:$D$2010,roboczykarol!$L$3:$L$2010),H8="Hurtowa",XLOOKUP(B8,roboczykarol!$D$3:$D$2010,roboczykarol!$N$3:$N$2010))} -> 48.5 | J8: {=IFS(H8="Hurtowa",XLOOKUP(B8,roboczykarol!$D$3:$D$2010,roboczykarol!$O$3:$O$2010),H8="Detaliczna",round(XLOOKUP(B8,roboczykarol!$D$3:$D$2010,roboczykarol!$M$3:$M$2010),1))} -> 59.655 | K8: netto | L8: 23
A9: Kształtka Kozel L90PZ z osłoną mleczną LIGER-22 | B9: 342 | G9: 1 | H9: Detaliczna | I9: {=IFS(H9="detaliczna",XLOOKUP(B9,roboczykarol!$D$3:$D$2010,roboczykarol!$L$3:$L$2010),H9="Hurtowa",XLOOKUP(B9,roboczykarol!$D$3:$D$2010,roboczykarol!$N$3:$N$2010))} -> 60.650407 | J9: {=IFS(H9="Hurtowa",XLOOKUP(B9,roboczykarol!$D$3:$D$2010,roboczykarol!$O$3:$O$2010),H9="Detaliczna",round(XLOOKUP(B9,roboczykarol!$D$3:$D$2010,roboczykarol!$M$3:$M$2010),1))} -> 74.6 | K9: netto | L9: 23
